Workbook

Sheet rekapan max llg
A1: CODE BARANG | B1: NAMA BARANG | C1: KATEGORI | D1: stock | E1: HASIL MIN | F1: HASIL MAX | G1: min% | H1: %max | L1: =COUNTIFS($G:$G,"<=10%") -> 173 | M1: =COUNTIFS($H:$H,">=150%") -> 88 | O1: =COUNTIFS($G:$G,"<=10%") -> 173 | P1: =COUNTIFS(H:H,">=150%") -> 88
A2: 8992696408869 | B2: NESCAFE CLASSIC 120GR | C2: BAVERAGE | D2: =VLOOKUP(Table1[[#This Row],[CODE BARANG]],stock!$A:$C,3,) -> 0 | E2: 70 | F2: 120 | G2: =Table1[[#This Row],[stock]]/Table1[[#This Row],[HASIL MIN]] -> 0 | H2: =Table1[[#This Row],[stock]]/Table1[[#This Row],[HASIL MAX]] -> 0 | K2: progres prio 1 LOLONG | N2: progres prio 1 LOLONG
A3: 8992993526907 | B3: COL GLAZE TIRAMISU 5KG | C3: FST | D3: =VLOOKUP(Table1[[#This Row],[CODE BARANG]],stock!$A:$C,3,) -> 0 | E3: 4 | F3: 16 | G3: =Table1[[#This Row],[stock]]/Table1[[#This Row],[HASIL MIN]] -> 0 | H3: =Table1[[#This Row],[stock]]/Table1[[#This Row],[HASIL MAX]] -> 0 | K3: tanggal | L3: under 10% | M3: over 150% | N3: tanggal | O3: under 10% | P3: over 150% | Q3: MAX UNDER 10% | R3: =MAX(O4:O34) -> 179
A4: 10410373 | B4: TP GULA WALET MAS 900GR | C4: FST | D4: =VLOOKUP(Table1[[#This Row],[CODE BARANG]],stock!$A:$C,3,) -> 0 | E4: 10 | F4: 20 | G4: =Table1[[#This Row],[stock]]/Table1[[#This Row],[HASIL MIN]] -> 0 | H4: =Table1[[#This Row],[stock]]/Table1[[#This Row],[HASIL MAX]] -> 0 | K4: 46204 | L4: 248 | M4: 175 | N4: 46204 | O4: 172 | P4: 71 | Q4: MIN UNDER 10% | R4: =MIN(O4:O34) -> 158
A5: 10411722 | B5: PLAZA FILLING PASTA C4 5KG | C5: FST | D5: =VLOOKUP(Table1[[#This Row],[CODE BARANG]],stock!$A:$C,3,) -> 0 | E5: 12 | F5: 18 | G5: =Table1[[#This Row],[stock]]/Table1[[#This Row],[HASIL MIN]] -> 0 | H5: =Table1[[#This Row],[stock]]/Table1[[#This Row],[HASIL MAX]] -> 0 | K5: 46175 | L5: 250 | M5: 174 | N5: 46205 | O5: 158 | P5: 75
A6: 8993007007153 | B6: INDOMILK FC PLAIN FOOD SERVICE 950ML | C6: BAVERAGE | D6: =VLOOKUP(Table1[[#This Row],[CODE BARANG]],stock!$A:$C,3,) -> 0 | E6: 360 | F6: 600 | G6: =Table1[[#This Row],[stock]]/Table1[[#This Row],[HASIL MIN]] -> 0 | H6: =Table1[[#This Row],[stock]]/Table1[[#This Row],[HASIL MAX]] -> 0 | K6: 46176 | L6: 236 | M6: 182 | N6: 46206 | O6: 169 | P6: 60 | Q6: MAX OVER 150% | R6: =MAX(P4:P34) -> 88
A7: 8993492101657 | B7: EDO PUFF PASTRY 750GR | C7: FROZEN | D7: =VLOOKUP(Table1[[#This Row],[CODE BARANG]],stock!$A:$C,3,) -> 0 | E7: 60 | F7: 120 | G7: =Table1[[#This Row],[stock]]/Table1[[#This Row],[HASIL MIN]] -> 0 | H7: =Table1[[#This Row],[stock]]/Table1[[#This Row],[HASIL MAX]] -> 0 | K7: 46177 | L7: 219 | M7: 188 | N7: 46207 | O7: 171 | P7: 56 | Q7: MIN OVER 150% | R7: =MIN(P4:P34) -> 51
A8: 8612491106 | B8: DENALI MATCHA 800GR | C8: BAVERAGE | D8: =VLOOKUP(Table1[[#This Row],[CODE BARANG]],stock!$A:$C,3,) -> 0 | E8: 10 | F8: 20 | G8: =Table1[[#This Row],[stock]]/Table1[[#This Row],[HASIL MIN]] -> 0 | H8: =Table1[[#This Row],[stock]]/Table1[[#This Row],[HASIL MAX]] -> 0 | K8: 46178 | L8: 225 | M8: 189 | N8: 46208 | O8: 178 | P8: 51
A9: 8992753721696 | B9: FF OMELA PLAIN 1000ML | C9: BAVERAGE | D9: =VLOOKUP(Table1[[#This Row],[CODE BARANG]],stock!$A:$C,3,) -> 0 | E9: 60 | F9: 120 | G9: =Table1[[#This Row],[stock]]/Table1[[#This Row],[HASIL MIN]] -> 0 | H9: =Table1[[#This Row],[stock]]/Table1[[#This Row],[HASIL MAX]] -> 0 | K9: 46179 | L9: 232 | M9: 183 | N9: 46209 | O9: 179 | P9: 53
A10: 10420569 | B10: LUNCH BOX L 50S | C10: PACKAGING | D10: =VLOOKUP(Table1[[#This Row],[CODE BARANG]],stock!$A:$C,3,) -> 0 | E10: 10 | F10: 20 | G10: =Table1[[#This Row],[stock]]/Table1[[#This Row],[HASIL MIN]] -> 0 | H10: =Table1[[#This Row],[stock]]/Table1[[#This Row],[HASIL MAX]] -> 0 | K10: 46180 | L10: 245 | M10: 177 | N10: 46210 | O10: 173 | P10: 65
A11: 8992984870125 | B11: KOEPOE GULA AREN 5L | C11: SWEETENER | D11: =VLOOKUP(Table1[[#This Row],[CODE BARANG]],stock!$A:$C,3,) -> 0 | E11: 6 | F11: 12 | G11: =Table1[[#This Row],[stock]]/Table1[[#This Row],[HASIL MIN]] -> 0 | H11: =Table1[[#This Row],[stock]]/Table1[[#This Row],[HASIL MAX]] -> 0 | K11: 46181 | L11: 228 | M11: 187 | N11: 46211 | O11: 171 | P11: 82
A12: 9415007038948 | B12: ANCHOR SLICE OREN 1.04KG | C12: CHILLED | D12: =VLOOKUP(Table1[[#This Row],[CODE BARANG]],stock!$A:$C,3,) -> 0 | E12: 6 | F12: 10 | G12: =Table1[[#This Row],[stock]]/Table1[[#This Row],[HASIL MIN]] -> 0 | H12: =Table1[[#This Row],[stock]]/Table1[[#This Row],[HASIL MAX]] -> 0 | K12: 46182 | L12: 227 | M12: 192 | N12: 46212 | O12: 176 | P12: 81
A13: 8997220500712 | B13: DRIPP BUTTERSCOTCH SYRUP 760ML | C13: BAVERAGE | D13: =VLOOKUP(Table1[[#This Row],[CODE BARANG]],stock!$A:$C,3,) -> 0 | E13: 4 | F13: 6 | G13: =Table1[[#This Row],[stock]]/Table1[[#This Row],[HASIL MIN]] -> 0 | H13: =Table1[[#This Row],[stock]]/Table1[[#This Row],[HASIL MAX]] -> 0 | K13: 46183 | L13: 228 | M13: 199 | N13: 46213 | O13: 173 | P13: 88
A14: 8993037582309 | B14: ROYAL KRONE BOS SALTED 20KG | C14: B & M | D14: =VLOOKUP(Table1[[#This Row],[CODE BARANG]],stock!$A:$C,3,) -> 0 | E14: 1 | F14: 2 | G14: =Table1[[#This Row],[stock]]/Table1[[#This Row],[HASIL MIN]] -> 0 | H14: =Table1[[#This Row],[stock]]/Table1[[#This Row],[HASIL MAX]] -> 0 | K14: 46184 | L14: 188 | M14: 219 | N14: 46214
A15: 8993319050120 | B15: GRANDAIRY FULL CREAM 1L | C15: BAVERAGE | D15: =VLOOKUP(Table1[[#This Row],[CODE BARANG]],stock!$A:$C,3,) -> 0 | E15: 60 | F15: 120 | G15: =Table1[[#This Row],[stock]]/Table1[[#This Row],[HASIL MIN]] -> 0 | H15: =Table1[[#This Row],[stock]]/Table1[[#This Row],[HASIL MAX]] -> 0 | K15: 46185 | L15: 196 | M15: 207 | N15: 46215
A16: 8992826116367 | B16: MG MITRA 2L | C16: P & D | D16: =VLOOKUP(Table1[[#This Row],[CODE BARANG]],stock!$A:$C,3,) -> 0 | E16: 18 | F16: 30 | G16: =Table1[[#This Row],[stock]]/Table1[[#This Row],[HASIL MIN]] -> 0 | H16: =Table1[[#This Row],[stock]]/Table1[[#This Row],[HASIL MAX]] -> 0 | K16: 46186 | L16: 192 | M16: 202 | N16: 46216
A17: 9311931504200 | B17: MAX TEA LEMON TEA 30 SACHET | C17: BAVERAGE | D17: =VLOOKUP(Table1[[#This Row],[CODE BARANG]],stock!$A:$C,3,) -> 0 | E17: 6 | F17: 12 | G17: =Table1[[#This Row],[stock]]/Table1[[#This Row],[HASIL MIN]] -> 0 | H17: =Table1[[#This Row],[stock]]/Table1[[#This Row],[HASIL MAX]] -> 0 | K17: 46187 | L17: 192 | M17: 201 | N17: 46217
A18: 8612491101 | B18: DENALI DARK COCOA 800GR | C18: BAVERAGE | D18: =VLOOKUP(Table1[[#This Row],[CODE BARANG]],stock!$A:$C,3,) -> 0 | E18: 6 | F18: 10 | G18: =Table1[[#This Row],[stock]]/Table1[[#This Row],[HASIL MIN]] -> 0 | H18: =Table1[[#This Row],[stock]]/Table1[[#This Row],[HASIL MAX]] -> 0 | K18: 46188 | L18: 207 | M18: 194 | N18: 46218
A19: 8991999110219 | B19: MILK LIFE FRESH MILK 1L | C19: CHILLED | D19: =VLOOKUP(Table1[[#This Row],[CODE BARANG]],stock!$A:$C,3,) -> 0 | E19: 36 | F19: 60 | G19: =Table1[[#This Row],[stock]]/Table1[[#This Row],[HASIL MIN]] -> 0 | H19: =Table1[[#This Row],[stock]]/Table1[[#This Row],[HASIL MAX]] -> 0 | K19: 46189 | L19: 219 | M19: 190 | N19: 46219
A20: 8998888712288 | B20: DELMONTE BBQ SAUS 1KG | C20: CONDIMENT | D20: =VLOOKUP(Table1[[#This Row],[CODE BARANG]],stock!$A:$C,3,) -> 0 | E20: 24 | F20: 36 | G20: =Table1[[#This Row],[stock]]/Table1[[#This Row],[HASIL MIN]] -> 0 | H20: =Table1[[#This Row],[stock]]/Table1[[#This Row],[HASIL MAX]] -> 0 | K20: 46190 | L20: 189 | M20: 210 | N20: 46220
A21: 5410522513257 | B21: CALLEBAUT 811NV 2,5KG | C21: FST | D21: =VLOOKUP(Table1[[#This Row],[CODE BARANG]],stock!$A:$C,3,) -> 0 | E21: 2 | F21: 6 | G21: =Table1[[#This Row],[stock]]/Table1[[#This Row],[HASIL MIN]] -> 0 | H21: =Table1[[#This Row],[stock]]/Table1[[#This Row],[HASIL MAX]] -> 0 | K21: 46191 | L21: 192 | M21: 213 | N21: 46221
A22: 8992984870026 | B22: KOEPOE GULA CAIR 5LT | C22: SWEETENER | D22: =VLOOKUP(Table1[[#This Row],[CODE BARANG]],stock!$A:$C,3,) -> 0 | E22: 8 | F22: 12 | G22: =Table1[[#This Row],[stock]]/Table1[[#This Row],[HASIL MIN]] -> 0 | H22: =Table1[[#This Row],[stock]]/Table1[[#This Row],[HASIL MAX]] -> 0 | K22: 46192 | L22: 194 | M22: 212 | N22: 46222
A23: 10427155 | B23: PLAZA FILLING SOFT C8 5KG | C23: FST | D23: =VLOOKUP(Table1[[#This Row],[CODE BARANG]],stock!$A:$C,3,) -> 0 | E23: 2 | F23: 4 | G23: =Table1[[#This Row],[stock]]/Table1[[#This Row],[HASIL MIN]] -> 0 | H23: =Table1[[#This Row],[stock]]/Table1[[#This Row],[HASIL MAX]] -> 0 | K23: 46193 | L23: 204 | M23: 216 | N23: 46223
A24: 8992770011114 | B24: AJINOMOTO 1KG | C24: CONDIMENT | D24: =VLOOKUP(Table1[[#This Row],[CODE BARANG]],stock!$A:$C,3,) -> 0 | E24: 12 | F24: 20 | G24: =Table1[[#This Row],[stock]]/Table1[[#This Row],[HASIL MIN]] -> 0 | H24: =Table1[[#This Row],[stock]]/Table1[[#This Row],[HASIL MAX]] -> 0 | K24: 46194 | L24: 221 | M24: 214 | N24: 46224
A25: 4800361004688 | B25: NESTLE NESTEA LEMON TEA 1KG | C25: BAVERAGE | D25: =VLOOKUP(Table1[[#This Row],[CODE BARANG]],stock!$A:$C,3,) -> 0 | E25: 6 | F25: 8 | G25: =Table1[[#This Row],[stock]]/Table1[[#This Row],[HASIL MIN]] -> 0 | H25: =Table1[[#This Row],[stock]]/Table1[[#This Row],[HASIL MAX]] -> 0 | K25: 46195 | L25: 233 | M25: 195 | N25: 46225
... A34: 8992770088895 | B34: SAJIKU TPG BUMBU SERBAGUNA 900GR | C34: SAVOURY | D34: =VLOOKUP(Table1[[#This Row],[CODE BARANG]],stock!$A:$C,3,) -> 0 | E34: 12 | F34: 20 | G34: =Table1[[#This Row],[stock]]/Table1[[#This Row],[HASIL MIN]] -> 0 | H34: =Table1[[#This Row],[stock]]/Table1[[#This Row],[HASIL MAX]] -> 0 | K34: 46204 | L34: 197 | M34: 214 | N34: 46234
A35: 8997240600010 | B35: OATSIDE BARISTA BLEND 1L | C35: BAVERAGE | D35: =VLOOKUP(Table1[[#This Row],[CODE BARANG]],stock!$A:$C,3,) -> 0 | E35: 6 | F35: 12 | G35: =Table1[[#This Row],[stock]]/Table1[[#This Row],[HASIL MIN]] -> 0 | H35: =Table1[[#This Row],[stock]]/Table1[[#This Row],[HASIL MAX]] -> 0
A36: 10412362 | B36: ALKA SARI GULA AREN SEMUT 1KG | C36: SWEETENER | D36: =VLOOKUP(Table1[[#This Row],[CODE BARANG]],stock!$A:$C,3,) -> 0 | E36: 6 | F36: 12 | G36: =Table1[[#This Row],[stock]]/Table1[[#This Row],[HASIL MIN]] -> 0 | H36: =Table1[[#This Row],[stock]]/Table1[[#This Row],[HASIL MAX]] -> 0
A37: 8997231730139 | B37: AROMANIS GULA AREN CAIR PREM 1.2KG | C37: SWEETENER | D37: =VLOOKUP(Table1[[#This Row],[CODE BARANG]],stock!$A:$C,3,) -> 0 | E37: 5 | F37: 10 | G37: =Table1[[#This Row],[stock]]/Table1[[#This Row],[HASIL MIN]] -> 0 | H37: =Table1[[#This Row],[stock]]/Table1[[#This Row],[HASIL MAX]] -> 0
A38: 8612535108 | B38: DENALI LYCHEE SYRUP 750ML | C38: BAVERAGE | D38: =VLOOKUP(Table1[[#This Row],[CODE BARANG]],stock!$A:$C,3,) -> 0 | E38: 6 | F38: 18 | G38: =Table1[[#This Row],[stock]]/Table1[[#This Row],[HASIL MIN]] -> 0 | H38: =Table1[[#This Row],[stock]]/Table1[[#This Row],[HASIL MAX]] -> 0
A39: 8997014035093 | B39: ELMER GLAZE TIRAMISU 5KG | C39: FST | D39: =VLOOKUP(Table1[[#This Row],[CODE BARANG]],stock!$A:$C,3,) -> 0 | E39: 3 | F39: 4 | G39: =Table1[[#This Row],[stock]]/Table1[[#This Row],[HASIL MIN]] -> 0 | H39: =Table1[[#This Row],[stock]]/Table1[[#This Row],[HASIL MAX]] -> 0
A40: 5410126146943 | B40: LOTUS CRUNCHY 380GR | C40: FST | D40: =VLOOKUP(Table1[[#This Row],[CODE BARANG]],stock!$A:$C,3,) -> 0 | E40: 12 | F40: 24 | G40: =Table1[[#This Row],[stock]]/Table1[[#This Row],[HASIL MIN]] -> 0 | H40: =Table1[[#This Row],[stock]]/Table1[[#This Row],[HASIL MAX]] -> 0
A41: 8612535102 | B41: DENALI CARAMEL SYRUP 750ML | C41: BAVERAGE | D41: =VLOOKUP(Table1[[#This Row],[CODE BARANG]],stock!$A:$C,3,) -> 0 | E41: 4 | F41: 6 | G41: =Table1[[#This Row],[stock]]/Table1[[#This Row],[HASIL MIN]] -> 0 | H41: =Table1[[#This Row],[stock]]/Table1[[#This Row],[HASIL MAX]] -> 0
A42: 8997014039527 | B42: PLAZA GLAZE ECO G. TEA 5KG | C42: FST | D42: =VLOOKUP(Table1[[#This Row],[CODE BARANG]],stock!$A:$C,3,) -> 0 | E42: 2 | F42: 4 | G42: =Table1[[#This Row],[stock]]/Table1[[#This Row],[HASIL MIN]] -> 0 | H42: =Table1[[#This Row],[stock]]/Table1[[#This Row],[HASIL MAX]] -> 0
A43: 8993351121307 | B43: GREENFIELDS FC MILK 1KG | C43: BAVERAGE | D43: =VLOOKUP(Table1[[#This Row],[CODE BARANG]],stock!$A:$C,3,) -> 0 | E43: 60 | F43: 120 | G43: =Table1[[#This Row],[stock]]/Table1[[#This Row],[HASIL MIN]] -> 0 | H43: =Table1[[#This Row],[stock]]/Table1[[#This Row],[HASIL MAX]] -> 0
A44: 8612535101 | B44: DENALI VANILLA SYRUP 750ML | C44: BAVERAGE | D44: =VLOOKUP(Table1[[#This Row],[CODE BARANG]],stock!$A:$C,3,) -> 0 | E44: 6 | F44: 18 | G44: =Table1[[#This Row],[stock]]/Table1[[#This Row],[HASIL MIN]] -> 0 | H44: =Table1[[#This Row],[stock]]/Table1[[#This Row],[HASIL MAX]] -> 0
A45: 8998888110411 | B45: MARJAN BOUDOIN LEMON 460ML | C45: BAVERAGE | D45: =VLOOKUP(Table1[[#This Row],[CODE BARANG]],stock!$A:$C,3,) -> 0 | E45: 6 | F45: 12 | G45: =Table1[[#This Row],[stock]]/Table1[[#This Row],[HASIL MIN]] -> 0 | H45: =Table1[[#This Row],[stock]]/Table1[[#This Row],[HASIL MAX]] -> 0
A46: 8993492102432 | B46: EDO DANISH PASTRY 750GR | C46: FROZEN | D46: =VLOOKUP(Table1[[#This Row],[CODE BARANG]],stock!$A:$C,3,) -> 0 | E46: 12 | F46: 24 | G46: =Table1[[#This Row],[stock]]/Table1[[#This Row],[HASIL MIN]] -> 0 | H46: =Table1[[#This Row],[stock]]/Table1[[#This Row],[HASIL MAX]] -> 0
... A1001: 10410604 | B1001: ANCHOR MOZARELLA 1KG | C1001: CHILLED | D1001: =VLOOKUP(Table1[[#This Row],[CODE BARANG]],stock!$A:$C,3,) -> 37.83 | E1001: 10 | F1001: 12 | G1001: =Table1[[#This Row],[stock]]/Table1[[#This Row],[HASIL MIN]] -> #VALUE! | H1001: =Table1[[#This Row],[stock]]/Table1[[#This Row],[HASIL MAX]] -> #VALUE!

Sheet stock
A1: Kode Barang | B1: Nama Barang | C1: Stock Akhir
A2: 49800063570 | B2: RICHS CHOCOLATE 907G | C2: 2
A3: 49800177031 | B3: RICHS VALUE PRIDE 907 GR | C3: 0
A4: 11210000018 | B4: TABASCO PEPPER SAUCE 60ML | C4: 18
A5: 11210000155 | B5: TABASCO PEPPER SAUCE 150ML | C5: 12
A6: 11210006508 | B6: TABASCO HABANERO SAUCE 60ML | C6: 11
A7: 11210007253 | B7: TABASCO GARLIC PEPPER SAUCE 60ML | C7: 29
A8: 11747234160 | B8: DOLPIN GARAM 250GR | C8: 76
A9: 11747234191 | B9: DOLPIN GARAM 500GR | C9: 31
A10: 11747234207 | B10: DOLPIN GARAM 1KG | C10: 36
A11: 117472342177 | B11: DOLPIN GARAM BTL 200GR | C11: 18
A12: 13000008129 | B12: CUKA APEL HEINZ 473ML | C12: 9
A13: 13000008525 | B13: CUKA WHITE HEINZ 473ML | C13: 7
... A313: 10200097 | B313: GULA PASIR 1KG | C313: 161
A314: 10200099 | B314: TATURA CRM CHEESE 1KG | C314: 0.01
A315: 10200105 | B315: SELASIH 1/2KG | C315: 0
A316: 10200108 | B316: MAKARONI JELAWAT 1KG | C316: 44
A317: 10200109 | B317: RAGI TAPAI NKL | C317: 28
A318: 10200115 | B318: SELASIH 250GR | C318: 6
A319: 10200117 | B319: ADAS MANIS BLT 100GR | C319: 11
A320: 10200118 | B320: MALINDA PTH 1KG | C320: 39
A321: 10200150 | B321: PEKAK 100GR | C321: 14
A322: 10200151 | B322: JINTAN HTM BLT 250GR | C322: 0
A323: 10200154 | B323: TORTILA MINI | C323: 6
A324: 10200160 | B324: GV GELATINE HALAL 250GR | C324: 0
A325: 10200161 | B325: GV GELATINE HALAL 100GR | C325: 0
A326: 10200163 | B326: KACANG MORIN 250GR | C326: 7
... A716: 10410603 | B716: ELMER AFRICAN BLCK 1/2KG | C716: 0
A717: 10410604 | B717: ANCHOR MOZARELLA 1KG | C717: 37.83
A718: 10410605 | B718: PURAVITA GANDUM 1/2KG | C718: 4
A719: 10410606 | B719: ALMOND SLICE 250gr | C719: 22
A720: 10410607 | B720: BASIL 10GR | C720: 46
A721: 10410609 | B721: ELMER AFRICAN BLCK 100GR | C721: 0
A722: 10410611 | B722: DANISH PASTRY 1/2KG | C722: 52
A723: 10410612 | B723: DANISH PASTRY 250GR | C723: 16
A724: 10410614 | B724: OREGANO 10GR | C724: 1
A725: 10410615 | B725: ALMOND UTUH 1/2KG | C725: 3
A726: 10410616 | B726: DYNA CUSTARD PWD 250GR | C726: 8
A727: 10410617 | B727: LADAME PASTA 100ML | C727: 3
A728: 10410621 | B728: ELMER COMP CAPUCINO 1S | C728: 38
...

Sheet Sheet2
A1: 1 | B1: 2 | C1: 3 | D1: 4 | E1: 5 | F1: 6 | G1: 7 | H1: 8 | I1: 9
A2: Kode | B2: Nama | C2: Kelp.Satuan | D2: Kelp.Volume | E2: LOLONG | H2: LOLONG
E3: TAG | F3: AKTIF | G3: MIN | H3: MIN 2 | I3: MAX 2
A4: 10411585 | B4: AB MAURI RED BEAN PASTE 5KG | C4: CRT-PCS | D4: 46026 | E4: S | F4: Ya | G4: 2
A5: 9916500118002 | B5: ABBYS BAKSO SAPI KECIL 370GR | C5: CRT-PCS | D5: 46032 | E5: D | F5: Tidak | G5: 1
A6: 711844120082 | B6: ABC EXTRA PEDAS 135ML | C6: CRT-PCS | D6: 48-1 | E6: S | F6: Ya | G6: 2
A7: 711844120532 | B7: ABC EXTRA PEDAS 380GR | C7: CRT-PCS | D7: 46034 | E7: M | F7: Ya | G7: 12 | H7: 12 | I7: 24
A8: 711844120556 | B8: ABC EXTRA PEDAS 75GR | C8: CRT-PCS | D8: 48-1 | E8: S | F8: Ya | G8: 4
A9: 711844120501 | B9: ABC EXTRA PEDAS 950GR | C9: CRT-PCS | D9: 46028 | E9: F1 | F9: Ya | G9: 60 | H9: 60 | I9: 80
A10: 711844110519 | B10: ABC KCP JRG 6KG | C10: PCS | D10: 1 | E10: M | F10: Ya | G10: 10 | H10: 10 | I10: 15
A11: 711844110144 | B11: ABC KCP MANIS 250ML | C11: CRT-PCS | D11: 46046 | E11: S | F11: Ya | G11: 4
A12: 711844115057 | B12: ABC KECAP ASIN 131ML | C12: CRT-PCS | D12: 48-1 | E12: M | F12: Ya | G12: 8
A13: 711844115033 | B13: ABC KECAP ASIN 620ML | C13: CRT-PCS | D13: 46034 | E13: M | F13: Ya | G13: 24 | H13: 24 | I13: 36
A14: 711844110762 | B14: ABC KECAP EXTRA PDS 135ML | C14: CRT-PCS | D14: 48-1 | E14: S | F14: Ya | G14: 4
A15: 711844140127 | B15: ABC KECAP INGGRIS 195ML | C15: CRT-PCS | D15: 46046 | E15: S | F15: Ya | G15: 8
A16: 711844110113 | B16: ABC KECAP MANIS 130ML | C16: CRT-PCS | D16: 48-1 | E16: S | F16: Ya | G16: 4
A17: 8994907000428 | B17: ABC KECAP MANIS 15ML | C17: CRT-PCS | D17: 288-1 | E17: S | F17: Ya | G17: 20
A18: 711844110083 | B18: ABC KECAP MANIS 275ML | C18: CRT-PCS | D18: 46046 | E18: S | F18: Ya | G18: 4
A19: 8994907003603 | B19: ABC KECAP MANIS 600GR | C19: CRT-PCS | D19: 46034 | E19: M | F19: Ya | G19: 10
A20: 711844110052 | B20: ABC KECAP MANIS 620ML | C20: CRT-PCS | D20: 46034 | E20: S | F20: Ya | G20: 4
A21: 711844110182 | B21: ABC KECAP MANIS 65ML | C21: CRT-PCS | D21: 48-1 | E21: S | F21: Ya | G21: 5
A22: 711844110205 | B22: ABC KECAP MANIS HOKI 520ML | C22: CRT-PCS | D22: 46034 | E22: S | F22: Ya | G22: 4
A23: 711844110700 | B23: ABC KECAP MANIS PEDAS 135ML | C23: CRT-PCS | D23: 48-1 | E23: S | F23: Ya | G23: 4
A24: 711844110717 | B24: ABC KECAP MANIS PEDAS 275ML | C24: CRT-PCS | D24: 46046 | E24: D | F24: Ya | G24: 1
A25: 8991002101968 | B25: ABC KOPI SUSU GULA AREN 297GR | C25: CRT-PCS | D25: 46042 | E25: S | F25: Ya | G25: 4
A26: 711844120013 | B26: ABC SAMB ASLI BB 335 ML | C26: CRT-PCS | D26: 46046 | E26: S | F26: Ya | G26: 3
A27: 711844120150 | B27: ABC SAMB AYAM GORENG 335ML | C27: CRT-PCS | D27: 46046 | E27: S | F27: Ya | G27: 2
A28: 711844120075 | B28: ABC SAMB EXTR PEDAS BB 335 ML | C28: CRT-PCS | D28: 46046 | E28: S | F28: Ya | G28: 2
A29: 711844120099 | B29: ABC SAMB MP BB 335 ML | C29: CRT-PCS | D29: 46046 | E29: S | F29: Ya | G29: 2
A30: 711844120037 | B30: ABC SAMBAL ASLI 135ML | C30: CRT-PCS | D30: 48-1 | E30: M | F30: Ya | G30: 4
A31: 711844120358 | B31: ABC SAMBAL ASLI 1KG | C31: CRT-PCS | D31: 46028 | E31: F | F31: Ya | G31: 30 | H31: 30 | I31: 60
A32: 711844120624 | B32: ABC SAMBAL ASLI 24 KG | C32: PCS | D32: 1 | E32: S | F32: Ya | G32: 4 | H32: 4 | I32: 6
A33: 711844120525 | B33: ABC SAMBAL ASLI 380GR | C33: CRT-PCS | D33: 46034 | E33: M | F33: Ya | G33: 5
A34: 711844120617 | B34: ABC SAMBAL ASLI 5,5KG | C34: PCS | D34: 1 | E34: F | F34: Ya | G34: 20 | H34: 20 | I34: 25
A35: 711844120549 | B35: ABC SAMBAL ASLI 75GR | C35: CRT-PCS | D35: 48-1 | E35: S | F35: Ya | G35: 5
A36: 711844120310 | B36: ABC SAMBAL ASLI 8GR | C36: CRT-PCS | D36: 46043 | E36: M | F36: Ya | G36: 42 | H36: 42 | I36: 72
A37: 711844120419 | B37: ABC SAMBAL ASLI BTL 275ML | C37: CRT-PCS | D37: 46046 | E37: M | F37: Ya | G37: 8
A38: 711844120433 | B38: ABC SAMBAL ASLI BTL 600ML | C38: CRT-PCS | D38: 46034 | E38: S | F38: Ya | G38: 4
A39: 8994907003450 | B39: ABC SAMBAL ASLI PCH 690GR | C39: CRT-PCS | D39: 46028 | E39: D | F39: Ya | G39: 2
A40: 711844120167 | B40: ABC SAMBAL AYM GORENG 135ML | C40: CRT-PCS | D40: 48-1 | E40: S | F40: Ya | G40: 4
...
